Workbook

Sheet Summary
A1: Rule adherence test report -- schedule v98
A2: Adherence % per check = followed / occurrences. PASS >= 99.5 %, PARTIAL 80-99.5 %, FAIL < 80 %. Report-only rows, rules without plant data and not-applicable rules are listed on 'Checks' but not scored.
A4: Section | B4: Checks scored | C4: PASS | D4: PARTIAL | E4: FAIL | F4: No data / report / not scored | G4: Average adherence % (per check) | H4: Occurrence-weighted adherence %
A5: Building & curing | B5: =COUNTIFS(Checks!$A$2:$A$111,$A5,Checks!$F$2:$F$111,"<>") | C5: =COUNTIFS(Checks!$A$2:$A$111,$A5,Checks!$G$2:$G$111,"PASS") | D5: =COUNTIFS(Checks!$A$2:$A$111,$A5,Checks!$G$2:$G$111,"PARTIAL") | E5: =COUNTIFS(Checks!$A$2:$A$111,$A5,Checks!$G$2:$G$111,"FAIL") | F5: =COUNTIFS(Checks!$A$2:$A$111,$A5)-B5 | G5: =IFERROR(AVERAGEIFS(Checks!$F$2:$F$111,Checks!$A$2:$A$111,$A5),"") | H5: =IFERROR(SUMPRODUCT((Checks!$A$2:$A$111=$A5)*(Checks!$F$2:$F$111<>"")*Checks!$E$2:$E$111)/SUMPRODUCT((Checks!$A$2:$A$111=$A5)*(Checks!$F$2:$F$111<>"")*Checks!$D$2:$D$111)*100,"")
A6: Mixing | B6: =COUNTIFS(Checks!$A$2:$A$111,$A6,Checks!$F$2:$F$111,"<>") | C6: =COUNTIFS(Checks!$A$2:$A$111,$A6,Checks!$G$2:$G$111,"PASS") | D6: =COUNTIFS(Checks!$A$2:$A$111,$A6,Checks!$G$2:$G$111,"PARTIAL") | E6: =COUNTIFS(Checks!$A$2:$A$111,$A6,Checks!$G$2:$G$111,"FAIL") | F6: =COUNTIFS(Checks!$A$2:$A$111,$A6)-B6 | G6: =IFERROR(AVERAGEIFS(Checks!$F$2:$F$111,Checks!$A$2:$A$111,$A6),"") | H6: =IFERROR(SUMPRODUCT((Checks!$A$2:$A$111=$A6)*(Checks!$F$2:$F$111<>"")*Checks!$E$2:$E$111)/SUMPRODUCT((Checks!$A$2:$A$111=$A6)*(Checks!$F$2:$F$111<>"")*Checks!$D$2:$D$111)*100,"")
A7: Mixing (rules 01-Oct + v47) | B7: =COUNTIFS(Checks!$A$2:$A$111,$A7,Checks!$F$2:$F$111,"<>") | C7: =COUNTIFS(Checks!$A$2:$A$111,$A7,Checks!$G$2:$G$111,"PASS") | D7: =COUNTIFS(Checks!$A$2:$A$111,$A7,Checks!$G$2:$G$111,"PARTIAL") | E7: =COUNTIFS(Checks!$A$2:$A$111,$A7,Checks!$G$2:$G$111,"FAIL") | F7: =COUNTIFS(Checks!$A$2:$A$111,$A7)-B7 | G7: =IFERROR(AVERAGEIFS(Checks!$F$2:$F$111,Checks!$A$2:$A$111,$A7),"") | H7: =IFERROR(SUMPRODUCT((Checks!$A$2:$A$111=$A7)*(Checks!$F$2:$F$111<>"")*Checks!$E$2:$E$111)/SUMPRODUCT((Checks!$A$2:$A$111=$A7)*(Checks!$F$2:$F$111<>"")*Checks!$D$2:$D$111)*100,"")
A8: MPQ | B8: =COUNTIFS(Checks!$A$2:$A$111,$A8,Checks!$F$2:$F$111,"<>") | C8: =COUNTIFS(Checks!$A$2:$A$111,$A8,Checks!$G$2:$G$111,"PASS") | D8: =COUNTIFS(Checks!$A$2:$A$111,$A8,Checks!$G$2:$G$111,"PARTIAL") | E8: =COUNTIFS(Checks!$A$2:$A$111,$A8,Checks!$G$2:$G$111,"FAIL") | F8: =COUNTIFS(Checks!$A$2:$A$111,$A8)-B8 | G8: =IFERROR(AVERAGEIFS(Checks!$F$2:$F$111,Checks!$A$2:$A$111,$A8),"") | H8: =IFERROR(SUMPRODUCT((Checks!$A$2:$A$111=$A8)*(Checks!$F$2:$F$111<>"")*Checks!$E$2:$E$111)/SUMPRODUCT((Checks!$A$2:$A$111=$A8)*(Checks!$F$2:$F$111<>"")*Checks!$D$2:$D$111)*100,"")
A9: 4-roll calender (901) | B9: =COUNTIFS(Checks!$A$2:$A$111,$A9,Checks!$F$2:$F$111,"<>") | C9: =COUNTIFS(Checks!$A$2:$A$111,$A9,Checks!$G$2:$G$111,"PASS") | D9: =COUNTIFS(Checks!$A$2:$A$111,$A9,Checks!$G$2:$G$111,"PARTIAL") | E9: =COUNTIFS(Checks!$A$2:$A$111,$A9,Checks!$G$2:$G$111,"FAIL") | F9: =COUNTIFS(Checks!$A$2:$A$111,$A9)-B9 | G9: =IFERROR(AVERAGEIFS(Checks!$F$2:$F$111,Checks!$A$2:$A$111,$A9),"") | H9: =IFERROR(SUMPRODUCT((Checks!$A$2:$A$111=$A9)*(Checks!$F$2:$F$111<>"")*Checks!$E$2:$E$111)/SUMPRODUCT((Checks!$A$2:$A$111=$A9)*(Checks!$F$2:$F$111<>"")*Checks!$D$2:$D$111)*100,"")
A10: Extrusion - Quintoplex (1002) | B10: =COUNTIFS(Checks!$A$2:$A$111,$A10,Checks!$F$2:$F$111,"<>") | C10: =COUNTIFS(Checks!$A$2:$A$111,$A10,Checks!$G$2:$G$111,"PASS") | D10: =COUNTIFS(Checks!$A$2:$A$111,$A10,Checks!$G$2:$G$111,"PARTIAL") | E10: =COUNTIFS(Checks!$A$2:$A$111,$A10,Checks!$G$2:$G$111,"FAIL") | F10: =COUNTIFS(Checks!$A$2:$A$111,$A10)-B10 | G10: =IFERROR(AVERAGEIFS(Checks!$F$2:$F$111,Checks!$A$2:$A$111,$A10),"") | H10: =IFERROR(SUMPRODUCT((Checks!$A$2:$A$111=$A10)*(Checks!$F$2:$F$111<>"")*Checks!$E$2:$E$111)/SUMPRODUCT((Checks!$A$2:$A$111=$A10)*(Checks!$F$2:$F$111<>"")*Checks!$D$2:$D$111)*100,"")
A11: Extrusion - Duplex (1801) | B11: =COUNTIFS(Checks!$A$2:$A$111,$A11,Checks!$F$2:$F$111,"<>") | C11: =COUNTIFS(Checks!$A$2:$A$111,$A11,Checks!$G$2:$G$111,"PASS") | D11: =COUNTIFS(Checks!$A$2:$A$111,$A11,Checks!$G$2:$G$111,"PARTIAL") | E11: =COUNTIFS(Checks!$A$2:$A$111,$A11,Checks!$G$2:$G$111,"FAIL") | F11: =COUNTIFS(Checks!$A$2:$A$111,$A11)-B11 | G11: =IFERROR(AVERAGEIFS(Checks!$F$2:$F$111,Checks!$A$2:$A$111,$A11),"") | H11: =IFERROR(SUMPRODUCT((Checks!$A$2:$A$111=$A11)*(Checks!$F$2:$F$111<>"")*Checks!$E$2:$E$111)/SUMPRODUCT((Checks!$A$2:$A$111=$A11)*(Checks!$F$2:$F$111<>"")*Checks!$D$2:$D$111)*100,"")
A12: Extrusion - Triplex (1001) | B12: =COUNTIFS(Checks!$A$2:$A$111,$A12,Checks!$F$2:$F$111,"<>") | C12: =COUNTIFS(Checks!$A$2:$A$111,$A12,Checks!$G$2:$G$111,"PASS") | D12: =COUNTIFS(Checks!$A$2:$A$111,$A12,Checks!$G$2:$G$111,"PARTIAL") | E12: =COUNTIFS(Checks!$A$2:$A$111,$A12,Checks!$G$2:$G$111,"FAIL") | F12: =COUNTIFS(Checks!$A$2:$A$111,$A12)-B12 | G12: =IFERROR(AVERAGEIFS(Checks!$F$2:$F$111,Checks!$A$2:$A$111,$A12),"") | H12: =IFERROR(SUMPRODUCT((Checks!$A$2:$A$111=$A12)*(Checks!$F$2:$F$111<>"")*Checks!$E$2:$E$111)/SUMPRODUCT((Checks!$A$2:$A$111=$A12)*(Checks!$F$2:$F$111<>"")*Checks!$D$2:$D$111)*100,"")
A13: Extrusion - Quadraplex (1803) | B13: =COUNTIFS(Checks!$A$2:$A$111,$A13,Checks!$F$2:$F$111,"<>") | C13: =COUNTIFS(Checks!$A$2:$A$111,$A13,Checks!$G$2:$G$111,"PASS") | D13: =COUNTIFS(Checks!$A$2:$A$111,$A13,Checks!$G$2:$G$111,"PARTIAL") | E13: =COUNTIFS(Checks!$A$2:$A$111,$A13,Checks!$G$2:$G$111,"FAIL") | F13: =COUNTIFS(Checks!$A$2:$A$111,$A13)-B13 | G13: =IFERROR(AVERAGEIFS(Checks!$F$2:$F$111,Checks!$A$2:$A$111,$A13),"") | H13: =IFERROR(SUMPRODUCT((Checks!$A$2:$A$111=$A13)*(Checks!$F$2:$F$111<>"")*Checks!$E$2:$E$111)/SUMPRODUCT((Checks!$A$2:$A$111=$A13)*(Checks!$F$2:$F$111<>"")*Checks!$D$2:$D$111)*100,"")
A14: General rules | B14: =COUNTIFS(Checks!$A$2:$A$111,$A14,Checks!$F$2:$F$111,"<>") | C14: =COUNTIFS(Checks!$A$2:$A$111,$A14,Checks!$G$2:$G$111,"PASS") | D14: =COUNTIFS(Checks!$A$2:$A$111,$A14,Checks!$G$2:$G$111,"PARTIAL") | E14: =COUNTIFS(Checks!$A$2:$A$111,$A14,Checks!$G$2:$G$111,"FAIL") | F14: =COUNTIFS(Checks!$A$2:$A$111,$A14)-B14 | G14: =IFERROR(AVERAGEIFS(Checks!$F$2:$F$111,Checks!$A$2:$A$111,$A14),"") | H14: =IFERROR(SUMPRODUCT((Checks!$A$2:$A$111=$A14)*(Checks!$F$2:$F$111<>"")*Checks!$E$2:$E$111)/SUMPRODUCT((Checks!$A$2:$A$111=$A14)*(Checks!$F$2:$F$111<>"")*Checks!$D$2:$D$111)*100,"")
A15: IL / calendering | B15: =COUNTIFS(Checks!$A$2:$A$111,$A15,Checks!$F$2:$F$111,"<>") | C15: =COUNTIFS(Checks!$A$2:$A$111,$A15,Checks!$G$2:$G$111,"PASS") | D15: =COUNTIFS(Checks!$A$2:$A$111,$A15,Checks!$G$2:$G$111,"PARTIAL") | E15: =COUNTIFS(Checks!$A$2:$A$111,$A15,Checks!$G$2:$G$111,"FAIL") | F15: =COUNTIFS(Checks!$A$2:$A$111,$A15)-B15 | G15: =IFERROR(AVERAGEIFS(Checks!$F$2:$F$111,Checks!$A$2:$A$111,$A15),"") | H15: =IFERROR(SUMPRODUCT((Checks!$A$2:$A$111=$A15)*(Checks!$F$2:$F$111<>"")*Checks!$E$2:$E$111)/SUMPRODUCT((Checks!$A$2:$A$111=$A15)*(Checks!$F$2:$F$111<>"")*Checks!$D$2:$D$111)*100,"")
A16: ALL RULES | B16: =SUM(B5:B15) | C16: =SUM(C5:C15) | D16: =SUM(D5:D15) | E16: =SUM(E5:E15) | F16: =SUM(F5:F15) | G16: =AVERAGE(Checks!$F$2:$F$111) | H16: =SUMPRODUCT((Checks!$F$2:$F$111<>"")*Checks!$E$2:$E$111)/SUMPRODUCT((Checks!$F$2:$F$111<>"")*Checks!$D$2:$D$111)*100
A18: Source data: live JK_CTP_PPDS / jkplanning_CTP tables of the run (see README_v98.md); check workbooks *_v98.xlsx in the same folder.

Sheet Checks
A1: section | B1: rule | C1: test | D1: occurrences | E1: followed | F1: adherence % | G1: status | H1: note | I1: source tables
A2: Building & curing | B2: B1 building eligibility | C2: build row on a TBM its GT is routed to | D2: 1395 | E2: 1378 | F2: 98.78 | G2: PARTIAL | H2: 0 rows whose GT has no GT BUILDING routing; 7 rows whose GT differs from the routing GT of the SKU | I2: JK_CTP_PPDS.CTP_Master_Routing; JK_CTP_PPDS.CTP_Master_ChangeoverMatrix; plan files (latest_plan_file)
A3: Building & curing | B3: B2 building capacity | C3: TBM-day: build + changeovers x different-size time <= available (PCR at BJ 60, TBR 24) | D3: 249 | E3: 249 | F3: 100 | G3: PASS | I3: JK_CTP_PPDS.CTP_Master_Routing; JK_CTP_PPDS.CTP_Master_ChangeoverMatrix; plan files (latest_plan_file)
A4: Building & curing | B4: B2 building capacity | C4: PCR TBM-day at CONTI 42 min | D4: 141 | E4: 141 | F4: 100 | G4: PASS | I4: JK_CTP_PPDS.CTP_Master_Routing; JK_CTP_PPDS.CTP_Master_ChangeoverMatrix; plan files (latest_plan_file)
A5: Building & curing | B5: B2 building capacity | C5: lot run time = qty x routing cycle / efficiency (+-1 min) | D5: 855 | E5: 855 | F5: 100 | G5: PASS | I5: JK_CTP_PPDS.CTP_Master_Routing; JK_CTP_PPDS.CTP_Master_ChangeoverMatrix; plan files (latest_plan_file)
A6: Building & curing | B6: B2 building capacity | C6: changeover: gap before the new GT >= different-size time (BJ for PCR) | D6: 358 | E6: 358 | F6: 100 | G6: PASS | I6: JK_CTP_PPDS.CTP_Master_Routing; JK_CTP_PPDS.CTP_Master_ChangeoverMatrix; plan files (latest_plan_file)
A7: Building & curing | B7: B2 building capacity | C7: changeover: gap before the new GT >= different-size time (CONTI for PCR) | D7: 358 | E7: 358 | F7: 100 | G7: PASS | I7: JK_CTP_PPDS.CTP_Master_Routing; JK_CTP_PPDS.CTP_Master_ChangeoverMatrix; plan files (latest_plan_file)
A8: Building & curing | B8: C1 curing eligibility | C8: cure block on a press allowed by the routing | D8: 4903 | E8: 4873 | F8: 99.39 | G8: PARTIAL | H8: 30 blocks whose SKU has no CURING routing | I8: JK_CTP_PPDS.CTP_Master_Routing; JK_CTP_PPDS.CTP_Master_ChangeoverMatrix; plan files (latest_plan_file)
A9: Building & curing | B9: C2 curing capacity | C9: line-day: cure minutes (q_shift rate) <= presses x available | D9: 28 | E9: 28 | F9: 100 | G9: PASS | I9: JK_CTP_PPDS.CTP_Master_Routing; JK_CTP_PPDS.CTP_Master_ChangeoverMatrix; plan files (latest_plan_file)
A10: Building & curing | B10: C2 curing capacity | C10: press-day: cure minutes (q_shift rate) <= available | D10: 2065 | E10: 2065 | F10: 100 | G10: PASS | I10: JK_CTP_PPDS.CTP_Master_Routing; JK_CTP_PPDS.CTP_Master_ChangeoverMatrix; plan files (latest_plan_file)
A11: Building & curing | B11: C2 curing capacity | C11: cure block qty <= q_shift (tyres a press cures in a shift) | D11: 4903 | E11: 4903 | F11: 100 | G11: PASS | I11: JK_CTP_PPDS.CTP_Master_Routing; JK_CTP_PPDS.CTP_Master_ChangeoverMatrix; plan files (latest_plan_file)
A12: Building & curing | B12: C2 curing capacity | C12: cure block: schedule cycleTime = routing cure time | D12: 4825 | E12: 4825 | F12: 100 | G12: PASS | H12: info | I12: JK_CTP_PPDS.CTP_Master_Routing; JK_CTP_PPDS.CTP_Master_ChangeoverMatrix; plan files (latest_plan_file)
A13: Building & curing | B13: C2 curing capacity | C13: press blocks do not overlap | D13: 4903 | E13: 4903 | F13: 100 | G13: PASS | I13: JK_CTP_PPDS.CTP_Master_Routing; JK_CTP_PPDS.CTP_Master_ChangeoverMatrix; plan files (latest_plan_file)
A14: Mixing | B14: BR-V1 | C14: mixer shift row in whole batches | D14: 567 | E14: 567 | F14: 100 | G14: PASS | I14: JK_CTP_PPDS.CTP_Master_Routing; JK_CTP_PPDS.CTP_Master_BOM
A15: Mixing | B15: BRM-01 | C15: mixing lot >= 5 batches (MPQ) | D15: 545 | E15: 545 | F15: 100 | G15: PASS | I15: JK_CTP_PPDS.CTP_Master_Routing; JK_CTP_PPDS.CTP_Master_BOM
A16: Mixing | B16: BRM-02 | C16: sticky lot in stacks of 3 batches | D16: 22 | E16: 22 | F16: 100 | G16: PASS | I16: JK_CTP_PPDS.CTP_Master_Routing; JK_CTP_PPDS.CTP_Master_BOM
A17: Mixing | B17: BRM-10 | C17: compound change on a mixer, gap >= 1 min | D17: 475 | E17: 475 | F17: 100 | G17: PASS | I17: JK_CTP_PPDS.CTP_Master_Routing; JK_CTP_PPDS.CTP_Master_BOM
A18: Mixing | B18: BRM-06 | C18: master<->final switch with TR100 clean-out | D18: 6 | E18: 6 | F18: 100 | G18: PASS | H18: gap >= 6 min (1 min changeover + 5 min TR100) | I18: JK_CTP_PPDS.CTP_Master_Routing; JK_CTP_PPDS.CTP_Master_BOM
A19: Mixing | B19: BRM-03 / BR-V2 | C19: transition at a butyl / protected compound | D19: 33 | E19: 33 | F19: 100 | G19: PASS | H19: in sequence, or clean-out >= required (final 120 s; master: changeover only) | I19: JK_CTP_PPDS.CTP_Master_Routing; JK_CTP_PPDS.CTP_Master_BOM
A20: Mixing | B20: BR-V2 prep in front | C20: 30G run starts right after B1/B2/B99 (or inside a butyl block that starts right after B1/B2/B99) | D20: 6 | E20: 6 | F20: 100 | G20: PASS | I20: JK_CTP_PPDS.CTP_Master_Routing; JK_CTP_PPDS.CTP_Master_BOM
A21: Mixing | B21: BR-V2 prep in front | C21: IL3 run starts right after B1/B2/B99 or its IL family (or inside a butyl block that starts right after B1/B2/B99) | D21: 7 | E21: 7 | F21: 100 | G21: PASS | I21: JK_CTP_PPDS.CTP_Master_Routing; JK_CTP_PPDS.CTP_Master_BOM
A22: Mixing | B22: BR-V2 prep in front | C22: IL5 run starts right after B1/B2/B99 or its IL family (or inside a butyl block that starts right after B1/B2/B99) | D22: 8 | E22: 8 | F22: 100 | G22: PASS | I22: JK_CTP_PPDS.CTP_Master_Routing; JK_CTP_PPDS.CTP_Master_BOM
A23: Mixing | B23: BRM-09 | C23: (mixer, shift, compound) as one run | D23: 484 | E23: 484 | F23: 100 | G23: PASS | I23: JK_CTP_PPDS.CTP_Master_Routing; JK_CTP_PPDS.CTP_Master_BOM
A24: Mixing | B24: BRM-11 | C24: mixing lot on a plant-allowed mixer | D24: 545 | E24: 545 | F24: 100 | G24: PASS | I24: JK_CTP_PPDS.CTP_Master_Routing; JK_CTP_PPDS.CTP_Master_BOM
A25: Mixing | B25: 3.1.3 / BRM-07 | C25: plant day (07:00->07:00) with exactly one IL campaign | D25: 12 | E25: 12 | F25: 100 | G25: PASS | I25: JK_CTP_PPDS.CTP_Master_Routing; JK_CTP_PPDS.CTP_Master_BOM
A26: Mixing | B26: 3.1.3 | C26: IL campaign with a butyl-friendly (B1/B2/B99) in front of its butyl block | D26: 12 | E26: 12 | F26: 100 | G26: PASS | I26: JK_CTP_PPDS.CTP_Master_Routing; JK_CTP_PPDS.CTP_Master_BOM
A27: Mixing | B27: BRM-12 | C27: plant-approved mixing cycle time | D27: 0 | E27: 0 | G27: NOT SCORED | H27: NOT SCORED: setting: runtime = qty / routing proc_time x efficiency | I27: JK_CTP_PPDS.CTP_Master_Routing; JK_CTP_PPDS.CTP_Master_BOM
A28: Mixing | B28: BRM-13 | C28: +5 buffer batches per compound | D28: 0 | E28: 0 | G28: NOT SCORED | H28: NOT SCORED: setting: buffer_batches = 5 on each compound's last lot | I28: JK_CTP_PPDS.CTP_Master_Routing; JK_CTP_PPDS.CTP_Master_BOM
A29: Mixing | B29: BRM-05 | C29: ML405/ML406 followed by MK3 | D29: 0 | E29: 0 | G29: NOT SCORED | H29: NOT SCORED: not applicable: no MK3 demand in this plan | I29: JK_CTP_PPDS.CTP_Master_Routing; JK_CTP_PPDS.CTP_Master_BOM
A30: Mixing | B30: BRM-04 | C30: K4 sequencing around IL compounds | D30: 0 | E30: 0 | G30: NOT SCORED | H30: NOT SCORED: not modelled (plant: 'confirm for CTP') | I30: JK_CTP_PPDS.CTP_Master_Routing; JK_CTP_PPDS.CTP_Master_BOM
A31: Mixing | B31: BRM-08 | C31: both finals of one master consecutively | D31: 0 | E31: 0 | G31: NOT SCORED | H31: NOT SCORED: not modelled (plant: 'confirm for CTP') | I31: JK_CTP_PPDS.CTP_Master_Routing; JK_CTP_PPDS.CTP_Master_BOM
A32: Mixing (rules 01-Oct + v47) | B32: Final Mixer – Before Butyl | C32: A Butyl-friendly compound (B1, B2, B99) must run immediately before a Butyl block (30G, IL3, IL5 -- butyl compounds may follow each other inside the block with the 120 s clean-out); user 10-Oct, as the plant. | D32: 21 | E32: 21 | F32: 100 | G32: PASS | I32: JK_CTP_PPDS.CTP_Master_Routing; JK_CTP_PPDS.CTP_Master_BOM; JK_CTP_PPDS.CTP_Master_FRC
A33: Mixing (rules 01-Oct + v47) | B33: Final Mixer – After Butyl | C33: After running a Butyl compound, a mandatory 120-second clean-out must be provided: final 30G / IL3 / IL5 and (rule text) 29MG / ML405 / ML605 ('ML045 / ML065'); gap to the next compound >= 120 s. | D33: 17 | E33: 17 | F33: 100 | G33: PASS | I33: JK_CTP_PPDS.CTP_Master_Routing; JK_CTP_PPDS.CTP_Master_BOM; JK_CTP_PPDS.CTP_Master_FRC
A34: Mixing (rules 01-Oct + v47) | B34: Master Mixer – Butyl Sequence | C34: A Butyl-friendly compound (MB100, MB200, XMB98) must run immediately before and after the Butyl block (29MG, ML405, ML605 together, 120 s clean-out between them); user 10-Oct, as the plant. | D34: 0 | E34: 0 | G34: REPORT | I34: JK_CTP_PPDS.CTP_Master_Routing; JK_CTP_PPDS.CTP_Master_BOM; JK_CTP_PPDS.CTP_Master_FRC
A35: Mixing (rules 01-Oct + v47) | B35: 430-2 Master Mixer – Final Compound | C35: When a final compound (T638) is run on the 430-2 Master Mixer, a mandatory 120-second clean-out must be provided both before and after the compound. | D35: 51 | E35: 51 | F35: 100 | G35: PASS | I35: JK_CTP_PPDS.CTP_Master_Routing; JK_CTP_PPDS.CTP_Master_BOM; JK_CTP_PPDS.CTP_Master_FRC
A36: Mixing (rules 01-Oct + v47) | B36: IL3 and IL5 together in one go a day | C36: IL3 and IL5 made together in the final mixer in ONE go once a day: B99 -> IL3 -> IL5 back to back (each compound once, no other compound between). | D36: 12 | E36: 12 | F36: 100 | G36: PASS | I36: JK_CTP_PPDS.CTP_Master_Routing; JK_CTP_PPDS.CTP_Master_BOM; JK_CTP_PPDS.CTP_Master_FRC
A37: Mixing (rules 01-Oct + v47) | B37: Mixing output in batches | C37: The mixing output should be in terms of batches, not KG. | D37: 567 | E37: 567 | F37: 100 | G37: PASS | I37: JK_CTP_PPDS.CTP_Master_Routing; JK_CTP_PPDS.CTP_Master_BOM; JK_CTP_PPDS.CTP_Master_FRC
A38: Mixing (rules 01-Oct + v47) | B38: One compound in one mixer per day | C38: One compound should be planned in only one mixer per plant day (07:00 -> 07:00) and not split across multiple mixers. | D38: 394 | E38: 394 | F38: 100 | G38: PASS | I38: JK_CTP_PPDS.CTP_Master_Routing; JK_CTP_PPDS.CTP_Master_BOM; JK_CTP_PPDS.CTP_Master_FRC
A39: Mixing (rules 01-Oct + v47) | B39: Same compound not repeated within 15 h (24 h IL / 4RC) | C39: A new run of the same compound starts at least 15 h after the previous run of it started (24 h for IL3 / IL5 and the 4RC compounds); butyl-friendly compounds exempt (config mixing_v47.exempt). | D39: 391 | E39: 391 | F39: 100 | G39: PASS | I39: JK_CTP_PPDS.CTP_Master_Routing; JK_CTP_PPDS.CTP_Master_BOM; JK_CTP_PPDS.CTP_Master_FRC
A40: Mixing (rules 01-Oct + v47) | B40: Final compound – clean-out after | C40: After running every final compound, a mandatory 120-second clean-out must be provided before the next compound (user 13-Oct). | D40: 472 | E40: 472 | F40: 100 | G40: PASS | I40: JK_CTP_PPDS.CTP_Master_Routing; JK_CTP_PPDS.CTP_Master_BOM; JK_CTP_PPDS.CTP_Master_FRC
...
